Traceback (most recent call last):
  File "/home/engavqti/abontemapp/passenger_wsgi.py", line 1, in <module>
    from abontem.wsgi import application
  File "/home/engavqti/abontemapp/abontem/wsgi.py", line 16, in <module>
    application = get_wsgi_application()
  File "/home/engavqti/virtualenv/abontemapp/3.8/lib/python3.8/site-packages/django/core/wsgi.py", line 12, in get_wsgi_application
    django.setup(set_prefix=False)
  File "/home/engavqti/virtualenv/abontemapp/3.8/lib/python3.8/site-packages/django/__init__.py", line 24, in setup
    apps.populate(settings.INSTALLED_APPS)
  File "/home/engavqti/virtualenv/abontemapp/3.8/lib/python3.8/site-packages/django/apps/registry.py", line 116, in populate
    app_config.import_models()
  File "/home/engavqti/virtualenv/abontemapp/3.8/lib/python3.8/site-packages/django/apps/config.py", line 304, in import_models
    self.models_module = import_module(models_module_name)
  File "/opt/alt/python38/lib64/python3.8/importlib/__init__.py", line 127, in import_module
    return _bootstrap._gcd_import(name[level:], package, level)
  File "/home/engavqti/abontemapp/farm/models.py", line 4, in <module>
    from django_countries.fields import CountryField
ModuleNotFoundError: No module named 'django_countries'
Traceback (most recent call last):
  File "/home/engavqti/abontemapp/passenger_wsgi.py", line 1, in <module>
    from abontem.wsgi import application
  File "/home/engavqti/abontemapp/abontem/wsgi.py", line 16, in <module>
    application = get_wsgi_application()
  File "/home/engavqti/virtualenv/abontemapp/3.8/lib/python3.8/site-packages/django/core/wsgi.py", line 12, in get_wsgi_application
    django.setup(set_prefix=False)
  File "/home/engavqti/virtualenv/abontemapp/3.8/lib/python3.8/site-packages/django/__init__.py", line 24, in setup
    apps.populate(settings.INSTALLED_APPS)
  File "/home/engavqti/virtualenv/abontemapp/3.8/lib/python3.8/site-packages/django/apps/registry.py", line 83, in populate
    raise RuntimeError("populate() isn't reentrant")
RuntimeError: populate() isn't reentrant
Traceback (most recent call last):
  File "/home/engavqti/abontemapp/passenger_wsgi.py", line 1, in <module>
    from abontem.wsgi import application
  File "/home/engavqti/abontemapp/abontem/wsgi.py", line 16, in <module>
    application = get_wsgi_application()
  File "/home/engavqti/virtualenv/abontemapp/3.8/lib/python3.8/site-packages/django/core/wsgi.py", line 12, in get_wsgi_application
    django.setup(set_prefix=False)
  File "/home/engavqti/virtualenv/abontemapp/3.8/lib/python3.8/site-packages/django/__init__.py", line 24, in setup
    apps.populate(settings.INSTALLED_APPS)
  File "/home/engavqti/virtualenv/abontemapp/3.8/lib/python3.8/site-packages/django/apps/registry.py", line 83, in populate
    raise RuntimeError("populate() isn't reentrant")
RuntimeError: populate() isn't reentrant
Traceback (most recent call last):
  File "/home/engavqti/abontemapp/passenger_wsgi.py", line 1, in <module>
    from abontem.wsgi import application
  File "/home/engavqti/abontemapp/abontem/wsgi.py", line 16, in <module>
    application = get_wsgi_application()
  File "/home/engavqti/virtualenv/abontemapp/3.8/lib/python3.8/site-packages/django/core/wsgi.py", line 12, in get_wsgi_application
    django.setup(set_prefix=False)
  File "/home/engavqti/virtualenv/abontemapp/3.8/lib/python3.8/site-packages/django/__init__.py", line 24, in setup
    apps.populate(settings.INSTALLED_APPS)
  File "/home/engavqti/virtualenv/abontemapp/3.8/lib/python3.8/site-packages/django/apps/registry.py", line 83, in populate
    raise RuntimeError("populate() isn't reentrant")
RuntimeError: populate() isn't reentrant
[ERROR] [UID:1454][1938493] wsgiAppHandler pApp->start_response() return NULL.
Traceback (most recent call last):
  File "/home/engavqti/virtualenv/abontemapp/3.8/lib/python3.8/site-packages/django/core/handlers/exception.py", line 55, in inner
    response = get_response(request)
  File "/home/engavqti/virtualenv/abontemapp/3.8/lib/python3.8/site-packages/django/core/handlers/base.py", line 181, in _get_response
    callback, callback_args, callback_kwargs = self.resolve_request(request)
  File "/home/engavqti/virtualenv/abontemapp/3.8/lib/python3.8/site-packages/django/core/handlers/base.py", line 313, in resolve_request
    resolver_match = resolver.resolve(request.path_info)
  File "/home/engavqti/virtualenv/abontemapp/3.8/lib/python3.8/site-packages/django/urls/resolvers.py", line 649, in resolve
    for pattern in self.url_patterns:
  File "/home/engavqti/virtualenv/abontemapp/3.8/lib/python3.8/site-packages/django/utils/functional.py", line 49, in __get__
    res = instance.__dict__[self.name] = self.func(instance)
  File "/home/engavqti/virtualenv/abontemapp/3.8/lib/python3.8/site-packages/django/urls/resolvers.py", line 696, in url_patterns
    patterns = getattr(self.urlconf_module, "urlpatterns", self.urlconf_module)
  File "/home/engavqti/virtualenv/abontemapp/3.8/lib/python3.8/site-packages/django/utils/functional.py", line 49, in __get__
    res = instance.__dict__[self.name] = self.func(instance)
  File "/home/engavqti/virtualenv/abontemapp/3.8/lib/python3.8/site-packages/django/urls/resolvers.py", line 689, in urlconf_module
    return import_module(self.urlconf_name)
  File "/opt/alt/python38/lib64/python3.8/importlib/__init__.py", line 127, in import_module
    return _bootstrap._gcd_import(name[level:], package, level)
  File "<frozen importlib._bootstrap>", line 1014, in _gcd_import
  File "<frozen importlib._bootstrap>", line 991, in _find_and_load
  File "<frozen importlib._bootstrap>", line 975, in _find_and_load_unlocked
  File "<frozen importlib._bootstrap>", line 671, in _load_unlocked
  File "<frozen importlib._bootstrap_external>", line 843, in exec_module
  File "<frozen importlib._bootstrap>", line 219, in _call_with_frames_removed
  File "/home/engavqti/abontemapp/abontem/urls.py", line 17, in <module>
    from farm import views
  File "/home/engavqti/abontemapp/farm/views.py", line 8, in <module>
    import requests
ModuleNotFoundError: No module named 'requests'

During handling of the above exception, another exception occurred:

Traceback (most recent call last):
  File "/home/engavqti/virtualenv/abontemapp/3.8/lib/python3.8/site-packages/django/core/handlers/exception.py", line 55, in inner
    response = get_response(request)
  File "/home/engavqti/virtualenv/abontemapp/3.8/lib/python3.8/site-packages/django/utils/deprecation.py", line 134, in __call__
    response = response or self.get_response(request)
  File "/home/engavqti/virtualenv/abontemapp/3.8/lib/python3.8/site-packages/django/core/handlers/exception.py", line 57, in inner
    response = response_for_exception(request, exc)
  File "/home/engavqti/virtualenv/abontemapp/3.8/lib/python3.8/site-packages/django/core/handlers/exception.py", line 139, in response_for_exception
    response = handle_uncaught_exception(
  File "/home/engavqti/virtualenv/abontemapp/3.8/lib/python3.8/site-packages/django/core/handlers/exception.py", line 183, in handle_uncaught_exception
    callback = resolver.resolve_error_handler(500)
  File "/home/engavqti/virtualenv/abontemapp/3.8/lib/python3.8/site-packages/django/urls/resolvers.py", line 710, in resolve_error_handler
    callback = getattr(self.urlconf_module, "handler%s" % view_type, None)
  File "/home/engavqti/virtualenv/abontemapp/3.8/lib/python3.8/site-packages/django/utils/functional.py", line 49, in __get__
    res = instance.__dict__[self.name] = self.func(instance)
  File "/home/engavqti/virtualenv/abontemapp/3.8/lib/python3.8/site-packages/django/urls/resolvers.py", line 689, in urlconf_module
    return import_module(self.urlconf_name)
  File "/opt/alt/python38/lib64/python3.8/importlib/__init__.py", line 127, in import_module
    return _bootstrap._gcd_import(name[level:], package, level)
  File "<frozen importlib._bootstrap>", line 1014, in _gcd_import
  File "<frozen importlib._bootstrap>", line 991, in _find_and_load
  File "<frozen importlib._bootstrap>", line 975, in _find_and_load_unlocked
  File "<frozen importlib._bootstrap>", line 671, in _load_unlocked
  File "<frozen importlib._bootstrap_external>", line 843, in exec_module
  File "<frozen importlib._bootstrap>", line 219, in _call_with_frames_removed
  File "/home/engavqti/abontemapp/abontem/urls.py", line 17, in <module>
    from farm import views
  File "/home/engavqti/abontemapp/farm/views.py", line 8, in <module>
    import requests
ModuleNotFoundError: No module named 'requests'

During handling of the above exception, another exception occurred:

Traceback (most recent call last):
  File "/home/engavqti/virtualenv/abontemapp/3.8/lib/python3.8/site-packages/django/core/handlers/exception.py", line 55, in inner
    response = get_response(request)
  File "/home/engavqti/virtualenv/abontemapp/3.8/lib/python3.8/site-packages/django/utils/deprecation.py", line 134, in __call__
    response = response or self.get_response(request)
  File "/home/engavqti/virtualenv/abontemapp/3.8/lib/python3.8/site-packages/django/core/handlers/exception.py", line 57, in inner
    response = response_for_exception(request, exc)
  File "/home/engavqti/virtualenv/abontemapp/3.8/lib/python3.8/site-packages/django/core/handlers/exception.py", line 139, in response_for_exception
    response = handle_uncaught_exception(
  File "/home/engavqti/virtualenv/abontemapp/3.8/lib/python3.8/site-packages/django/core/handlers/exception.py", line 183, in handle_uncaught_exception
    callback = resolver.resolve_error_handler(500)
  File "/home/engavqti/virtualenv/abontemapp/3.8/lib/python3.8/site-packages/django/urls/resolvers.py", line 710, in resolve_error_handler
    callback = getattr(self.urlconf_module, "handler%s" % view_type, None)
  File "/home/engavqti/virtualenv/abontemapp/3.8/lib/python3.8/site-packages/django/utils/functional.py", line 49, in __get__
    res = instance.__dict__[self.name] = self.func(instance)
  File "/home/engavqti/virtualenv/abontemapp/3.8/lib/python3.8/site-packages/django/urls/resolvers.py", line 689, in urlconf_module
    return import_module(self.urlconf_name)
  File "/opt/alt/python38/lib64/python3.8/importlib/__init__.py", line 127, in import_module
    return _bootstrap._gcd_import(name[level:], package, level)
  File "<frozen importlib._bootstrap>", line 1014, in _gcd_import
  File "<frozen importlib._bootstrap>", line 991, in _find_and_load
  File "<frozen importlib._bootstrap>", line 975, in _find_and_load_unlocked
  File "<frozen importlib._bootstrap>", line 671, in _load_unlocked
  File "<frozen importlib._bootstrap_external>", line 843, in exec_module
  File "<frozen importlib._bootstrap>", line 219, in _call_with_frames_removed
  File "/home/engavqti/abontemapp/abontem/urls.py", line 17, in <module>
    from farm import views
  File "/home/engavqti/abontemapp/farm/views.py", line 8, in <module>
    import requests
ModuleNotFoundError: No module named 'requests'

During handling of the above exception, another exception occurred:

Traceback (most recent call last):
  File "/home/engavqti/virtualenv/abontemapp/3.8/lib/python3.8/site-packages/django/core/handlers/exception.py", line 55, in inner
    response = get_response(request)
  File "/home/engavqti/virtualenv/abontemapp/3.8/lib/python3.8/site-packages/django/utils/deprecation.py", line 134, in __call__
    response = response or self.get_response(request)
  File "/home/engavqti/virtualenv/abontemapp/3.8/lib/python3.8/site-packages/django/core/handlers/exception.py", line 57, in inner
    response = response_for_exception(request, exc)
  File "/home/engavqti/virtualenv/abontemapp/3.8/lib/python3.8/site-packages/django/core/handlers/exception.py", line 139, in response_for_exception
    response = handle_uncaught_exception(
  File "/home/engavqti/virtualenv/abontemapp/3.8/lib/python3.8/site-packages/django/core/handlers/exception.py", line 183, in handle_uncaught_exception
    callback = resolver.resolve_error_handler(500)
  File "/home/engavqti/virtualenv/abontemapp/3.8/lib/python3.8/site-packages/django/urls/resolvers.py", line 710, in resolve_error_handler
    callback = getattr(self.urlconf_module, "handler%s" % view_type, None)
  File "/home/engavqti/virtualenv/abontemapp/3.8/lib/python3.8/site-packages/django/utils/functional.py", line 49, in __get__
    res = instance.__dict__[self.name] = self.func(instance)
  File "/home/engavqti/virtualenv/abontemapp/3.8/lib/python3.8/site-packages/django/urls/resolvers.py", line 689, in urlconf_module
    return import_module(self.urlconf_name)
  File "/opt/alt/python38/lib64/python3.8/importlib/__init__.py", line 127, in import_module
    return _bootstrap._gcd_import(name[level:], package, level)
  File "<frozen importlib._bootstrap>", line 1014, in _gcd_import
  File "<frozen importlib._bootstrap>", line 991, in _find_and_load
  File "<frozen importlib._bootstrap>", line 975, in _find_and_load_unlocked
  File "<frozen importlib._bootstrap>", line 671, in _load_unlocked
  File "<frozen importlib._bootstrap_external>", line 843, in exec_module
  File "<frozen importlib._bootstrap>", line 219, in _call_with_frames_removed
  File "/home/engavqti/abontemapp/abontem/urls.py", line 17, in <module>
    from farm import views
  File "/home/engavqti/abontemapp/farm/views.py", line 8, in <module>
    import requests
ModuleNotFoundError: No module named 'requests'

During handling of the above exception, another exception occurred:

Traceback (most recent call last):
  File "/home/engavqti/virtualenv/abontemapp/3.8/lib/python3.8/site-packages/django/core/handlers/exception.py", line 55, in inner
    response = get_response(request)
  File "/home/engavqti/virtualenv/abontemapp/3.8/lib/python3.8/site-packages/django/utils/deprecation.py", line 134, in __call__
    response = response or self.get_response(request)
  File "/home/engavqti/virtualenv/abontemapp/3.8/lib/python3.8/site-packages/django/core/handlers/exception.py", line 57, in inner
    response = response_for_exception(request, exc)
  File "/home/engavqti/virtualenv/abontemapp/3.8/lib/python3.8/site-packages/django/core/handlers/exception.py", line 139, in response_for_exception
    response = handle_uncaught_exception(
  File "/home/engavqti/virtualenv/abontemapp/3.8/lib/python3.8/site-packages/django/core/handlers/exception.py", line 183, in handle_uncaught_exception
    callback = resolver.resolve_error_handler(500)
  File "/home/engavqti/virtualenv/abontemapp/3.8/lib/python3.8/site-packages/django/urls/resolvers.py", line 710, in resolve_error_handler
    callback = getattr(self.urlconf_module, "handler%s" % view_type, None)
  File "/home/engavqti/virtualenv/abontemapp/3.8/lib/python3.8/site-packages/django/utils/functional.py", line 49, in __get__
    res = instance.__dict__[self.name] = self.func(instance)
  File "/home/engavqti/virtualenv/abontemapp/3.8/lib/python3.8/site-packages/django/urls/resolvers.py", line 689, in urlconf_module
    return import_module(self.urlconf_name)
  File "/opt/alt/python38/lib64/python3.8/importlib/__init__.py", line 127, in import_module
    return _bootstrap._gcd_import(name[level:], package, level)
  File "<frozen importlib._bootstrap>", line 1014, in _gcd_import
  File "<frozen importlib._bootstrap>", line 991, in _find_and_load
  File "<frozen importlib._bootstrap>", line 975, in _find_and_load_unlocked
  File "<frozen importlib._bootstrap>", line 671, in _load_unlocked
  File "<frozen importlib._bootstrap_external>", line 843, in exec_module
  File "<frozen importlib._bootstrap>", line 219, in _call_with_frames_removed
  File "/home/engavqti/abontemapp/abontem/urls.py", line 17, in <module>
    from farm import views
  File "/home/engavqti/abontemapp/farm/views.py", line 8, in <module>
    import requests
ModuleNotFoundError: No module named 'requests'

During handling of the above exception, another exception occurred:

Traceback (most recent call last):
  File "/home/engavqti/virtualenv/abontemapp/3.8/lib/python3.8/site-packages/django/core/handlers/exception.py", line 55, in inner
    response = get_response(request)
  File "/home/engavqti/virtualenv/abontemapp/3.8/lib/python3.8/site-packages/django/utils/deprecation.py", line 134, in __call__
    response = response or self.get_response(request)
  File "/home/engavqti/virtualenv/abontemapp/3.8/lib/python3.8/site-packages/django/core/handlers/exception.py", line 57, in inner
    response = response_for_exception(request, exc)
  File "/home/engavqti/virtualenv/abontemapp/3.8/lib/python3.8/site-packages/django/core/handlers/exception.py", line 139, in response_for_exception
    response = handle_uncaught_exception(
  File "/home/engavqti/virtualenv/abontemapp/3.8/lib/python3.8/site-packages/django/core/handlers/exception.py", line 183, in handle_uncaught_exception
    callback = resolver.resolve_error_handler(500)
  File "/home/engavqti/virtualenv/abontemapp/3.8/lib/python3.8/site-packages/django/urls/resolvers.py", line 710, in resolve_error_handler
    callback = getattr(self.urlconf_module, "handler%s" % view_type, None)
  File "/home/engavqti/virtualenv/abontemapp/3.8/lib/python3.8/site-packages/django/utils/functional.py", line 49, in __get__
    res = instance.__dict__[self.name] = self.func(instance)
  File "/home/engavqti/virtualenv/abontemapp/3.8/lib/python3.8/site-packages/django/urls/resolvers.py", line 689, in urlconf_module
    return import_module(self.urlconf_name)
  File "/opt/alt/python38/lib64/python3.8/importlib/__init__.py", line 127, in import_module
    return _bootstrap._gcd_import(name[level:], package, level)
  File "<frozen importlib._bootstrap>", line 1014, in _gcd_import
  File "<frozen importlib._bootstrap>", line 991, in _find_and_load
  File "<frozen importlib._bootstrap>", line 975, in _find_and_load_unlocked
  File "<frozen importlib._bootstrap>", line 671, in _load_unlocked
  File "<frozen importlib._bootstrap_external>", line 843, in exec_module
  File "<frozen importlib._bootstrap>", line 219, in _call_with_frames_removed
  File "/home/engavqti/abontemapp/abontem/urls.py", line 17, in <module>
    from farm import views
  File "/home/engavqti/abontemapp/farm/views.py", line 8, in <module>
    import requests
ModuleNotFoundError: No module named 'requests'

During handling of the above exception, another exception occurred:

Traceback (most recent call last):
  File "/home/engavqti/virtualenv/abontemapp/3.8/lib/python3.8/site-packages/django/core/handlers/exception.py", line 55, in inner
    response = get_response(request)
  File "/home/engavqti/virtualenv/abontemapp/3.8/lib/python3.8/site-packages/django/utils/deprecation.py", line 134, in __call__
    response = response or self.get_response(request)
  File "/home/engavqti/virtualenv/abontemapp/3.8/lib/python3.8/site-packages/django/core/handlers/exception.py", line 57, in inner
    response = response_for_exception(request, exc)
  File "/home/engavqti/virtualenv/abontemapp/3.8/lib/python3.8/site-packages/django/core/handlers/exception.py", line 139, in response_for_exception
    response = handle_uncaught_exception(
  File "/home/engavqti/virtualenv/abontemapp/3.8/lib/python3.8/site-packages/django/core/handlers/exception.py", line 183, in handle_uncaught_exception
    callback = resolver.resolve_error_handler(500)
  File "/home/engavqti/virtualenv/abontemapp/3.8/lib/python3.8/site-packages/django/urls/resolvers.py", line 710, in resolve_error_handler
    callback = getattr(self.urlconf_module, "handler%s" % view_type, None)
  File "/home/engavqti/virtualenv/abontemapp/3.8/lib/python3.8/site-packages/django/utils/functional.py", line 49, in __get__
    res = instance.__dict__[self.name] = self.func(instance)
  File "/home/engavqti/virtualenv/abontemapp/3.8/lib/python3.8/site-packages/django/urls/resolvers.py", line 689, in urlconf_module
    return import_module(self.urlconf_name)
  File "/opt/alt/python38/lib64/python3.8/importlib/__init__.py", line 127, in import_module
    return _bootstrap._gcd_import(name[level:], package, level)
  File "<frozen importlib._bootstrap>", line 1014, in _gcd_import
  File "<frozen importlib._bootstrap>", line 991, in _find_and_load
  File "<frozen importlib._bootstrap>", line 975, in _find_and_load_unlocked
  File "<frozen importlib._bootstrap>", line 671, in _load_unlocked
  File "<frozen importlib._bootstrap_external>", line 843, in exec_module
  File "<frozen importlib._bootstrap>", line 219, in _call_with_frames_removed
  File "/home/engavqti/abontemapp/abontem/urls.py", line 17, in <module>
    from farm import views
  File "/home/engavqti/abontemapp/farm/views.py", line 8, in <module>
    import requests
ModuleNotFoundError: No module named 'requests'

During handling of the above exception, another exception occurred:

Traceback (most recent call last):
  File "/home/engavqti/virtualenv/abontemapp/3.8/lib/python3.8/site-packages/django/core/handlers/exception.py", line 55, in inner
    response = get_response(request)
  File "/home/engavqti/virtualenv/abontemapp/3.8/lib/python3.8/site-packages/django/utils/deprecation.py", line 134, in __call__
    response = response or self.get_response(request)
  File "/home/engavqti/virtualenv/abontemapp/3.8/lib/python3.8/site-packages/django/core/handlers/exception.py", line 57, in inner
    response = response_for_exception(request, exc)
  File "/home/engavqti/virtualenv/abontemapp/3.8/lib/python3.8/site-packages/django/core/handlers/exception.py", line 139, in response_for_exception
    response = handle_uncaught_exception(
  File "/home/engavqti/virtualenv/abontemapp/3.8/lib/python3.8/site-packages/django/core/handlers/exception.py", line 183, in handle_uncaught_exception
    callback = resolver.resolve_error_handler(500)
  File "/home/engavqti/virtualenv/abontemapp/3.8/lib/python3.8/site-packages/django/urls/resolvers.py", line 710, in resolve_error_handler
    callback = getattr(self.urlconf_module, "handler%s" % view_type, None)
  File "/home/engavqti/virtualenv/abontemapp/3.8/lib/python3.8/site-packages/django/utils/functional.py", line 49, in __get__
    res = instance.__dict__[self.name] = self.func(instance)
  File "/home/engavqti/virtualenv/abontemapp/3.8/lib/python3.8/site-packages/django/urls/resolvers.py", line 689, in urlconf_module
    return import_module(self.urlconf_name)
  File "/opt/alt/python38/lib64/python3.8/importlib/__init__.py", line 127, in import_module
    return _bootstrap._gcd_import(name[level:], package, level)
  File "<frozen importlib._bootstrap>", line 1014, in _gcd_import
  File "<frozen importlib._bootstrap>", line 991, in _find_and_load
  File "<frozen importlib._bootstrap>", line 975, in _find_and_load_unlocked
  File "<frozen importlib._bootstrap>", line 671, in _load_unlocked
  File "<frozen importlib._bootstrap_external>", line 843, in exec_module
  File "<frozen importlib._bootstrap>", line 219, in _call_with_frames_removed
  File "/home/engavqti/abontemapp/abontem/urls.py", line 17, in <module>
    from farm import views
  File "/home/engavqti/abontemapp/farm/views.py", line 8, in <module>
    import requests
ModuleNotFoundError: No module named 'requests'

During handling of the above exception, another exception occurred:

Traceback (most recent call last):
  File "/home/engavqti/virtualenv/abontemapp/3.8/lib/python3.8/site-packages/django/core/handlers/exception.py", line 55, in inner
    response = get_response(request)
  File "/home/engavqti/virtualenv/abontemapp/3.8/lib/python3.8/site-packages/whitenoise/middleware.py", line 60, in __call__
    response = self.get_response(request)
  File "/home/engavqti/virtualenv/abontemapp/3.8/lib/python3.8/site-packages/django/core/handlers/exception.py", line 57, in inner
    response = response_for_exception(request, exc)
  File "/home/engavqti/virtualenv/abontemapp/3.8/lib/python3.8/site-packages/django/core/handlers/exception.py", line 139, in response_for_exception
    response = handle_uncaught_exception(
  File "/home/engavqti/virtualenv/abontemapp/3.8/lib/python3.8/site-packages/django/core/handlers/exception.py", line 183, in handle_uncaught_exception
    callback = resolver.resolve_error_handler(500)
  File "/home/engavqti/virtualenv/abontemapp/3.8/lib/python3.8/site-packages/django/urls/resolvers.py", line 710, in resolve_error_handler
    callback = getattr(self.urlconf_module, "handler%s" % view_type, None)
  File "/home/engavqti/virtualenv/abontemapp/3.8/lib/python3.8/site-packages/django/utils/functional.py", line 49, in __get__
    res = instance.__dict__[self.name] = self.func(instance)
  File "/home/engavqti/virtualenv/abontemapp/3.8/lib/python3.8/site-packages/django/urls/resolvers.py", line 689, in urlconf_module
    return import_module(self.urlconf_name)
  File "/opt/alt/python38/lib64/python3.8/importlib/__init__.py", line 127, in import_module
    return _bootstrap._gcd_import(name[level:], package, level)
  File "<frozen importlib._bootstrap>", line 1014, in _gcd_import
  File "<frozen importlib._bootstrap>", line 991, in _find_and_load
  File "<frozen importlib._bootstrap>", line 975, in _find_and_load_unlocked
  File "<frozen importlib._bootstrap>", line 671, in _load_unlocked
  File "<frozen importlib._bootstrap_external>", line 843, in exec_module
  File "<frozen importlib._bootstrap>", line 219, in _call_with_frames_removed
  File "/home/engavqti/abontemapp/abontem/urls.py", line 17, in <module>
    from farm import views
  File "/home/engavqti/abontemapp/farm/views.py", line 8, in <module>
    import requests
ModuleNotFoundError: No module named 'requests'

During handling of the above exception, another exception occurred:

Traceback (most recent call last):
  File "/home/engavqti/virtualenv/abontemapp/3.8/lib/python3.8/site-packages/django/core/handlers/exception.py", line 55, in inner
    response = get_response(request)
  File "/home/engavqti/virtualenv/abontemapp/3.8/lib/python3.8/site-packages/django/utils/deprecation.py", line 134, in __call__
    response = response or self.get_response(request)
  File "/home/engavqti/virtualenv/abontemapp/3.8/lib/python3.8/site-packages/django/core/handlers/exception.py", line 57, in inner
    response = response_for_exception(request, exc)
  File "/home/engavqti/virtualenv/abontemapp/3.8/lib/python3.8/site-packages/django/core/handlers/exception.py", line 139, in response_for_exception
    response = handle_uncaught_exception(
  File "/home/engavqti/virtualenv/abontemapp/3.8/lib/python3.8/site-packages/django/core/handlers/exception.py", line 183, in handle_uncaught_exception
    callback = resolver.resolve_error_handler(500)
  File "/home/engavqti/virtualenv/abontemapp/3.8/lib/python3.8/site-packages/django/urls/resolvers.py", line 710, in resolve_error_handler
    callback = getattr(self.urlconf_module, "handler%s" % view_type, None)
  File "/home/engavqti/virtualenv/abontemapp/3.8/lib/python3.8/site-packages/django/utils/functional.py", line 49, in __get__
    res = instance.__dict__[self.name] = self.func(instance)
  File "/home/engavqti/virtualenv/abontemapp/3.8/lib/python3.8/site-packages/django/urls/resolvers.py", line 689, in urlconf_module
    return import_module(self.urlconf_name)
  File "/opt/alt/python38/lib64/python3.8/importlib/__init__.py", line 127, in import_module
    return _bootstrap._gcd_import(name[level:], package, level)
  File "<frozen importlib._bootstrap>", line 1014, in _gcd_import
  File "<frozen importlib._bootstrap>", line 991, in _find_and_load
  File "<frozen importlib._bootstrap>", line 975, in _find_and_load_unlocked
  File "<frozen importlib._bootstrap>", line 671, in _load_unlocked
  File "<frozen importlib._bootstrap_external>", line 843, in exec_module
  File "<frozen importlib._bootstrap>", line 219, in _call_with_frames_removed
  File "/home/engavqti/abontemapp/abontem/urls.py", line 17, in <module>
    from farm import views
  File "/home/engavqti/abontemapp/farm/views.py", line 8, in <module>
    import requests
ModuleNotFoundError: No module named 'requests'

During handling of the above exception, another exception occurred:

Traceback (most recent call last):
  File "/home/engavqti/virtualenv/abontemapp/3.8/lib/python3.8/site-packages/django/core/handlers/wsgi.py", line 132, in __call__
    response = self.get_response(request)
  File "/home/engavqti/virtualenv/abontemapp/3.8/lib/python3.8/site-packages/django/core/handlers/base.py", line 140, in get_response
    response = self._middleware_chain(request)
  File "/home/engavqti/virtualenv/abontemapp/3.8/lib/python3.8/site-packages/django/core/handlers/exception.py", line 57, in inner
    response = response_for_exception(request, exc)
  File "/home/engavqti/virtualenv/abontemapp/3.8/lib/python3.8/site-packages/django/core/handlers/exception.py", line 139, in response_for_exception
    response = handle_uncaught_exception(
  File "/home/engavqti/virtualenv/abontemapp/3.8/lib/python3.8/site-packages/django/core/handlers/exception.py", line 183, in handle_uncaught_exception
    callback = resolver.resolve_error_handler(500)
  File "/home/engavqti/virtualenv/abontemapp/3.8/lib/python3.8/site-packages/django/urls/resolvers.py", line 710, in resolve_error_handler
    callback = getattr(self.urlconf_module, "handler%s" % view_type, None)
  File "/home/engavqti/virtualenv/abontemapp/3.8/lib/python3.8/site-packages/django/utils/functional.py", line 49, in __get__
    res = instance.__dict__[self.name] = self.func(instance)
  File "/home/engavqti/virtualenv/abontemapp/3.8/lib/python3.8/site-packages/django/urls/resolvers.py", line 689, in urlconf_module
    return import_module(self.urlconf_name)
  File "/opt/alt/python38/lib64/python3.8/importlib/__init__.py", line 127, in import_module
    return _bootstrap._gcd_import(name[level:], package, level)
  File "<frozen importlib._bootstrap>", line 1014, in _gcd_import
  File "<frozen importlib._bootstrap>", line 991, in _find_and_load
  File "<frozen importlib._bootstrap>", line 975, in _find_and_load_unlocked
  File "<frozen importlib._bootstrap>", line 671, in _load_unlocked
  File "<frozen importlib._bootstrap_external>", line 843, in exec_module
  File "<frozen importlib._bootstrap>", line 219, in _call_with_frames_removed
  File "/home/engavqti/abontemapp/abontem/urls.py", line 17, in <module>
    from farm import views
  File "/home/engavqti/abontemapp/farm/views.py", line 8, in <module>
    import requests
ModuleNotFoundError: No module named 'requests'
[ERROR] [UID:1454][1938493] wsgiAppHandler pApp->start_response() return NULL.
Traceback (most recent call last):
  File "/home/engavqti/virtualenv/abontemapp/3.8/lib/python3.8/site-packages/django/core/handlers/exception.py", line 55, in inner
    response = get_response(request)
  File "/home/engavqti/virtualenv/abontemapp/3.8/lib/python3.8/site-packages/django/utils/deprecation.py", line 133, in __call__
    response = self.process_request(request)
  File "/home/engavqti/virtualenv/abontemapp/3.8/lib/python3.8/site-packages/django/middleware/common.py", line 53, in process_request
    if self.should_redirect_with_slash(request):
  File "/home/engavqti/virtualenv/abontemapp/3.8/lib/python3.8/site-packages/django/middleware/common.py", line 70, in should_redirect_with_slash
    if not is_valid_path(request.path_info, urlconf):
  File "/home/engavqti/virtualenv/abontemapp/3.8/lib/python3.8/site-packages/django/urls/base.py", line 155, in is_valid_path
    return resolve(path, urlconf)
  File "/home/engavqti/virtualenv/abontemapp/3.8/lib/python3.8/site-packages/django/urls/base.py", line 24, in resolve
    return get_resolver(urlconf).resolve(path)
  File "/home/engavqti/virtualenv/abontemapp/3.8/lib/python3.8/site-packages/django/urls/resolvers.py", line 649, in resolve
    for pattern in self.url_patterns:
  File "/home/engavqti/virtualenv/abontemapp/3.8/lib/python3.8/site-packages/django/utils/functional.py", line 49, in __get__
    res = instance.__dict__[self.name] = self.func(instance)
  File "/home/engavqti/virtualenv/abontemapp/3.8/lib/python3.8/site-packages/django/urls/resolvers.py", line 696, in url_patterns
    patterns = getattr(self.urlconf_module, "urlpatterns", self.urlconf_module)
  File "/home/engavqti/virtualenv/abontemapp/3.8/lib/python3.8/site-packages/django/utils/functional.py", line 49, in __get__
    res = instance.__dict__[self.name] = self.func(instance)
  File "/home/engavqti/virtualenv/abontemapp/3.8/lib/python3.8/site-packages/django/urls/resolvers.py", line 689, in urlconf_module
    return import_module(self.urlconf_name)
  File "/opt/alt/python38/lib64/python3.8/importlib/__init__.py", line 127, in import_module
    return _bootstrap._gcd_import(name[level:], package, level)
  File "<frozen importlib._bootstrap>", line 1014, in _gcd_import
  File "<frozen importlib._bootstrap>", line 991, in _find_and_load
  File "<frozen importlib._bootstrap>", line 975, in _find_and_load_unlocked
  File "<frozen importlib._bootstrap>", line 671, in _load_unlocked
  File "<frozen importlib._bootstrap_external>", line 843, in exec_module
  File "<frozen importlib._bootstrap>", line 219, in _call_with_frames_removed
  File "/home/engavqti/abontemapp/abontem/urls.py", line 17, in <module>
    from farm import views
  File "/home/engavqti/abontemapp/farm/views.py", line 8, in <module>
    import requests
ModuleNotFoundError: No module named 'requests'

During handling of the above exception, another exception occurred:

Traceback (most recent call last):
  File "/home/engavqti/virtualenv/abontemapp/3.8/lib/python3.8/site-packages/django/core/handlers/exception.py", line 55, in inner
    response = get_response(request)
  File "/home/engavqti/virtualenv/abontemapp/3.8/lib/python3.8/site-packages/django/utils/deprecation.py", line 134, in __call__
    response = response or self.get_response(request)
  File "/home/engavqti/virtualenv/abontemapp/3.8/lib/python3.8/site-packages/django/core/handlers/exception.py", line 57, in inner
    response = response_for_exception(request, exc)
  File "/home/engavqti/virtualenv/abontemapp/3.8/lib/python3.8/site-packages/django/core/handlers/exception.py", line 139, in response_for_exception
    response = handle_uncaught_exception(
  File "/home/engavqti/virtualenv/abontemapp/3.8/lib/python3.8/site-packages/django/core/handlers/exception.py", line 183, in handle_uncaught_exception
    callback = resolver.resolve_error_handler(500)
  File "/home/engavqti/virtualenv/abontemapp/3.8/lib/python3.8/site-packages/django/urls/resolvers.py", line 710, in resolve_error_handler
    callback = getattr(self.urlconf_module, "handler%s" % view_type, None)
  File "/home/engavqti/virtualenv/abontemapp/3.8/lib/python3.8/site-packages/django/utils/functional.py", line 49, in __get__
    res = instance.__dict__[self.name] = self.func(instance)
  File "/home/engavqti/virtualenv/abontemapp/3.8/lib/python3.8/site-packages/django/urls/resolvers.py", line 689, in urlconf_module
    return import_module(self.urlconf_name)
  File "/opt/alt/python38/lib64/python3.8/importlib/__init__.py", line 127, in import_module
    return _bootstrap._gcd_import(name[level:], package, level)
  File "<frozen importlib._bootstrap>", line 1014, in _gcd_import
  File "<frozen importlib._bootstrap>", line 991, in _find_and_load
  File "<frozen importlib._bootstrap>", line 975, in _find_and_load_unlocked
  File "<frozen importlib._bootstrap>", line 671, in _load_unlocked
  File "<frozen importlib._bootstrap_external>", line 843, in exec_module
  File "<frozen importlib._bootstrap>", line 219, in _call_with_frames_removed
  File "/home/engavqti/abontemapp/abontem/urls.py", line 17, in <module>
    from farm import views
  File "/home/engavqti/abontemapp/farm/views.py", line 8, in <module>
    import requests
ModuleNotFoundError: No module named 'requests'

During handling of the above exception, another exception occurred:

Traceback (most recent call last):
  File "/home/engavqti/virtualenv/abontemapp/3.8/lib/python3.8/site-packages/django/core/handlers/exception.py", line 55, in inner
    response = get_response(request)
  File "/home/engavqti/virtualenv/abontemapp/3.8/lib/python3.8/site-packages/django/utils/deprecation.py", line 134, in __call__
    response = response or self.get_response(request)
  File "/home/engavqti/virtualenv/abontemapp/3.8/lib/python3.8/site-packages/django/core/handlers/exception.py", line 57, in inner
    response = response_for_exception(request, exc)
  File "/home/engavqti/virtualenv/abontemapp/3.8/lib/python3.8/site-packages/django/core/handlers/exception.py", line 139, in response_for_exception
    response = handle_uncaught_exception(
  File "/home/engavqti/virtualenv/abontemapp/3.8/lib/python3.8/site-packages/django/core/handlers/exception.py", line 183, in handle_uncaught_exception
    callback = resolver.resolve_error_handler(500)
  File "/home/engavqti/virtualenv/abontemapp/3.8/lib/python3.8/site-packages/django/urls/resolvers.py", line 710, in resolve_error_handler
    callback = getattr(self.urlconf_module, "handler%s" % view_type, None)
  File "/home/engavqti/virtualenv/abontemapp/3.8/lib/python3.8/site-packages/django/utils/functional.py", line 49, in __get__
    res = instance.__dict__[self.name] = self.func(instance)
  File "/home/engavqti/virtualenv/abontemapp/3.8/lib/python3.8/site-packages/django/urls/resolvers.py", line 689, in urlconf_module
    return import_module(self.urlconf_name)
  File "/opt/alt/python38/lib64/python3.8/importlib/__init__.py", line 127, in import_module
    return _bootstrap._gcd_import(name[level:], package, level)
  File "<frozen importlib._bootstrap>", line 1014, in _gcd_import
  File "<frozen importlib._bootstrap>", line 991, in _find_and_load
  File "<frozen importlib._bootstrap>", line 975, in _find_and_load_unlocked
  File "<frozen importlib._bootstrap>", line 671, in _load_unlocked
  File "<frozen importlib._bootstrap_external>", line 843, in exec_module
  File "<frozen importlib._bootstrap>", line 219, in _call_with_frames_removed
  File "/home/engavqti/abontemapp/abontem/urls.py", line 17, in <module>
    from farm import views
  File "/home/engavqti/abontemapp/farm/views.py", line 8, in <module>
    import requests
ModuleNotFoundError: No module named 'requests'

During handling of the above exception, another exception occurred:

Traceback (most recent call last):
  File "/home/engavqti/virtualenv/abontemapp/3.8/lib/python3.8/site-packages/django/core/handlers/exception.py", line 55, in inner
    response = get_response(request)
  File "/home/engavqti/virtualenv/abontemapp/3.8/lib/python3.8/site-packages/whitenoise/middleware.py", line 60, in __call__
    response = self.get_response(request)
  File "/home/engavqti/virtualenv/abontemapp/3.8/lib/python3.8/site-packages/django/core/handlers/exception.py", line 57, in inner
    response = response_for_exception(request, exc)
  File "/home/engavqti/virtualenv/abontemapp/3.8/lib/python3.8/site-packages/django/core/handlers/exception.py", line 139, in response_for_exception
    response = handle_uncaught_exception(
  File "/home/engavqti/virtualenv/abontemapp/3.8/lib/python3.8/site-packages/django/core/handlers/exception.py", line 183, in handle_uncaught_exception
    callback = resolver.resolve_error_handler(500)
  File "/home/engavqti/virtualenv/abontemapp/3.8/lib/python3.8/site-packages/django/urls/resolvers.py", line 710, in resolve_error_handler
    callback = getattr(self.urlconf_module, "handler%s" % view_type, None)
  File "/home/engavqti/virtualenv/abontemapp/3.8/lib/python3.8/site-packages/django/utils/functional.py", line 49, in __get__
    res = instance.__dict__[self.name] = self.func(instance)
  File "/home/engavqti/virtualenv/abontemapp/3.8/lib/python3.8/site-packages/django/urls/resolvers.py", line 689, in urlconf_module
    return import_module(self.urlconf_name)
  File "/opt/alt/python38/lib64/python3.8/importlib/__init__.py", line 127, in import_module
    return _bootstrap._gcd_import(name[level:], package, level)
  File "<frozen importlib._bootstrap>", line 1014, in _gcd_import
  File "<frozen importlib._bootstrap>", line 991, in _find_and_load
  File "<frozen importlib._bootstrap>", line 975, in _find_and_load_unlocked
  File "<frozen importlib._bootstrap>", line 671, in _load_unlocked
  File "<frozen importlib._bootstrap_external>", line 843, in exec_module
  File "<frozen importlib._bootstrap>", line 219, in _call_with_frames_removed
  File "/home/engavqti/abontemapp/abontem/urls.py", line 17, in <module>
    from farm import views
  File "/home/engavqti/abontemapp/farm/views.py", line 8, in <module>
    import requests
ModuleNotFoundError: No module named 'requests'

During handling of the above exception, another exception occurred:

Traceback (most recent call last):
  File "/home/engavqti/virtualenv/abontemapp/3.8/lib/python3.8/site-packages/django/core/handlers/exception.py", line 55, in inner
    response = get_response(request)
  File "/home/engavqti/virtualenv/abontemapp/3.8/lib/python3.8/site-packages/django/utils/deprecation.py", line 134, in __call__
    response = response or self.get_response(request)
  File "/home/engavqti/virtualenv/abontemapp/3.8/lib/python3.8/site-packages/django/core/handlers/exception.py", line 57, in inner
    response = response_for_exception(request, exc)
  File "/home/engavqti/virtualenv/abontemapp/3.8/lib/python3.8/site-packages/django/core/handlers/exception.py", line 139, in response_for_exception
    response = handle_uncaught_exception(
  File "/home/engavqti/virtualenv/abontemapp/3.8/lib/python3.8/site-packages/django/core/handlers/exception.py", line 183, in handle_uncaught_exception
    callback = resolver.resolve_error_handler(500)
  File "/home/engavqti/virtualenv/abontemapp/3.8/lib/python3.8/site-packages/django/urls/resolvers.py", line 710, in resolve_error_handler
    callback = getattr(self.urlconf_module, "handler%s" % view_type, None)
  File "/home/engavqti/virtualenv/abontemapp/3.8/lib/python3.8/site-packages/django/utils/functional.py", line 49, in __get__
    res = instance.__dict__[self.name] = self.func(instance)
  File "/home/engavqti/virtualenv/abontemapp/3.8/lib/python3.8/site-packages/django/urls/resolvers.py", line 689, in urlconf_module
    return import_module(self.urlconf_name)
  File "/opt/alt/python38/lib64/python3.8/importlib/__init__.py", line 127, in import_module
    return _bootstrap._gcd_import(name[level:], package, level)
  File "<frozen importlib._bootstrap>", line 1014, in _gcd_import
  File "<frozen importlib._bootstrap>", line 991, in _find_and_load
  File "<frozen importlib._bootstrap>", line 975, in _find_and_load_unlocked
  File "<frozen importlib._bootstrap>", line 671, in _load_unlocked
  File "<frozen importlib._bootstrap_external>", line 843, in exec_module
  File "<frozen importlib._bootstrap>", line 219, in _call_with_frames_removed
  File "/home/engavqti/abontemapp/abontem/urls.py", line 17, in <module>
    from farm import views
  File "/home/engavqti/abontemapp/farm/views.py", line 8, in <module>
    import requests
ModuleNotFoundError: No module named 'requests'

During handling of the above exception, another exception occurred:

Traceback (most recent call last):
  File "/home/engavqti/virtualenv/abontemapp/3.8/lib/python3.8/site-packages/django/core/handlers/wsgi.py", line 132, in __call__
    response = self.get_response(request)
  File "/home/engavqti/virtualenv/abontemapp/3.8/lib/python3.8/site-packages/django/core/handlers/base.py", line 140, in get_response
    response = self._middleware_chain(request)
  File "/home/engavqti/virtualenv/abontemapp/3.8/lib/python3.8/site-packages/django/core/handlers/exception.py", line 57, in inner
    response = response_for_exception(request, exc)
  File "/home/engavqti/virtualenv/abontemapp/3.8/lib/python3.8/site-packages/django/core/handlers/exception.py", line 139, in response_for_exception
    response = handle_uncaught_exception(
  File "/home/engavqti/virtualenv/abontemapp/3.8/lib/python3.8/site-packages/django/core/handlers/exception.py", line 183, in handle_uncaught_exception
    callback = resolver.resolve_error_handler(500)
  File "/home/engavqti/virtualenv/abontemapp/3.8/lib/python3.8/site-packages/django/urls/resolvers.py", line 710, in resolve_error_handler
    callback = getattr(self.urlconf_module, "handler%s" % view_type, None)
  File "/home/engavqti/virtualenv/abontemapp/3.8/lib/python3.8/site-packages/django/utils/functional.py", line 49, in __get__
    res = instance.__dict__[self.name] = self.func(instance)
  File "/home/engavqti/virtualenv/abontemapp/3.8/lib/python3.8/site-packages/django/urls/resolvers.py", line 689, in urlconf_module
    return import_module(self.urlconf_name)
  File "/opt/alt/python38/lib64/python3.8/importlib/__init__.py", line 127, in import_module
    return _bootstrap._gcd_import(name[level:], package, level)
  File "<frozen importlib._bootstrap>", line 1014, in _gcd_import
  File "<frozen importlib._bootstrap>", line 991, in _find_and_load
  File "<frozen importlib._bootstrap>", line 975, in _find_and_load_unlocked
  File "<frozen importlib._bootstrap>", line 671, in _load_unlocked
  File "<frozen importlib._bootstrap_external>", line 843, in exec_module
  File "<frozen importlib._bootstrap>", line 219, in _call_with_frames_removed
  File "/home/engavqti/abontemapp/abontem/urls.py", line 17, in <module>
    from farm import views
  File "/home/engavqti/abontemapp/farm/views.py", line 8, in <module>
    import requests
ModuleNotFoundError: No module named 'requests'
OpenBLAS blas_thread_init: pthread_create failed for thread 21 of 24: Resource temporarily unavailable
OpenBLAS blas_thread_init: RLIMIT_NPROC 1400 current, 1500 max
OpenBLAS blas_thread_init: pthread_create failed for thread 22 of 24: Resource temporarily unavailable
OpenBLAS blas_thread_init: RLIMIT_NPROC 1400 current, 1500 max
OpenBLAS blas_thread_init: pthread_create failed for thread 23 of 24: Resource temporarily unavailable
OpenBLAS blas_thread_init: RLIMIT_NPROC 1400 current, 1500 max
[ERROR] [UID:1454][2164029] wsgiAppHandler pApp->start_response() return NULL.
Traceback (most recent call last):
  File "/home/engavqti/virtualenv/abontemapp/3.8/lib/python3.8/site-packages/django/core/handlers/wsgi.py", line 132, in __call__
    response = self.get_response(request)
  File "/home/engavqti/virtualenv/abontemapp/3.8/lib/python3.8/site-packages/django/core/handlers/base.py", line 140, in get_response
    response = self._middleware_chain(request)
  File "/home/engavqti/virtualenv/abontemapp/3.8/lib/python3.8/site-packages/django/core/handlers/exception.py", line 55, in inner
    response = get_response(request)
  File "/home/engavqti/virtualenv/abontemapp/3.8/lib/python3.8/site-packages/django/utils/deprecation.py", line 134, in __call__
    response = response or self.get_response(request)
  File "/home/engavqti/virtualenv/abontemapp/3.8/lib/python3.8/site-packages/django/core/handlers/exception.py", line 55, in inner
    response = get_response(request)
  File "/home/engavqti/virtualenv/abontemapp/3.8/lib/python3.8/site-packages/whitenoise/middleware.py", line 60, in __call__
    response = self.get_response(request)
  File "/home/engavqti/virtualenv/abontemapp/3.8/lib/python3.8/site-packages/django/core/handlers/exception.py", line 55, in inner
    response = get_response(request)
  File "/home/engavqti/virtualenv/abontemapp/3.8/lib/python3.8/site-packages/django/utils/deprecation.py", line 134, in __call__
    response = response or self.get_response(request)
  File "/home/engavqti/virtualenv/abontemapp/3.8/lib/python3.8/site-packages/django/core/handlers/exception.py", line 55, in inner
    response = get_response(request)
  File "/home/engavqti/virtualenv/abontemapp/3.8/lib/python3.8/site-packages/django/utils/deprecation.py", line 134, in __call__
    response = response or self.get_response(request)
  File "/home/engavqti/virtualenv/abontemapp/3.8/lib/python3.8/site-packages/django/core/handlers/exception.py", line 55, in inner
    response = get_response(request)
  File "/home/engavqti/virtualenv/abontemapp/3.8/lib/python3.8/site-packages/django/utils/deprecation.py", line 133, in __call__
    response = self.process_request(request)
  File "/home/engavqti/virtualenv/abontemapp/3.8/lib/python3.8/site-packages/django/middleware/common.py", line 53, in process_request
    if self.should_redirect_with_slash(request):
  File "/home/engavqti/virtualenv/abontemapp/3.8/lib/python3.8/site-packages/django/middleware/common.py", line 70, in should_redirect_with_slash
    if not is_valid_path(request.path_info, urlconf):
  File "/home/engavqti/virtualenv/abontemapp/3.8/lib/python3.8/site-packages/django/urls/base.py", line 155, in is_valid_path
    return resolve(path, urlconf)
  File "/home/engavqti/virtualenv/abontemapp/3.8/lib/python3.8/site-packages/django/urls/base.py", line 24, in resolve
    return get_resolver(urlconf).resolve(path)
  File "/home/engavqti/virtualenv/abontemapp/3.8/lib/python3.8/site-packages/django/urls/resolvers.py", line 649, in resolve
    for pattern in self.url_patterns:
  File "/home/engavqti/virtualenv/abontemapp/3.8/lib/python3.8/site-packages/django/utils/functional.py", line 49, in __get__
    res = instance.__dict__[self.name] = self.func(instance)
  File "/home/engavqti/virtualenv/abontemapp/3.8/lib/python3.8/site-packages/django/urls/resolvers.py", line 696, in url_patterns
    patterns = getattr(self.urlconf_module, "urlpatterns", self.urlconf_module)
  File "/home/engavqti/virtualenv/abontemapp/3.8/lib/python3.8/site-packages/django/utils/functional.py", line 49, in __get__
    res = instance.__dict__[self.name] = self.func(instance)
  File "/home/engavqti/virtualenv/abontemapp/3.8/lib/python3.8/site-packages/django/urls/resolvers.py", line 689, in urlconf_module
    return import_module(self.urlconf_name)
  File "/opt/alt/python38/lib64/python3.8/importlib/__init__.py", line 127, in import_module
    return _bootstrap._gcd_import(name[level:], package, level)
  File "<frozen importlib._bootstrap>", line 1014, in _gcd_import
  File "<frozen importlib._bootstrap>", line 991, in _find_and_load
  File "<frozen importlib._bootstrap>", line 975, in _find_and_load_unlocked
  File "<frozen importlib._bootstrap>", line 671, in _load_unlocked
  File "<frozen importlib._bootstrap_external>", line 843, in exec_module
  File "<frozen importlib._bootstrap>", line 219, in _call_with_frames_removed
  File "/home/engavqti/abontemapp/abontem/urls.py", line 17, in <module>
    from farm import views
  File "/home/engavqti/abontemapp/farm/views.py", line 23, in <module>
    import pandas as pd
  File "/home/engavqti/virtualenv/abontemapp/3.8/lib64/python3.8/site-packages/pandas/__init__.py", line 11, in <module>
    __import__(dependency)
  File "/home/engavqti/virtualenv/abontemapp/3.8/lib64/python3.8/site-packages/numpy/__init__.py", line 150, in <module>
    from . import core
  File "/home/engavqti/virtualenv/abontemapp/3.8/lib64/python3.8/site-packages/numpy/core/__init__.py", line 22, in <module>
    from . import multiarray
  File "/home/engavqti/virtualenv/abontemapp/3.8/lib64/python3.8/site-packages/numpy/core/multiarray.py", line 12, in <module>
    from . import overrides
  File "/home/engavqti/virtualenv/abontemapp/3.8/lib64/python3.8/site-packages/numpy/core/overrides.py", line 7, in <module>
    from numpy.core._multiarray_umath import (
KeyboardInterrupt
[UID:1454][1938298] Child process with pid: 2164029 was killed by signal: 11, core dump: 0
OpenBLAS blas_thread_init: pthread_create failed for thread 12 of 24: Resource temporarily unavailable
OpenBLAS blas_thread_init: RLIMIT_NPROC 1400 current, 1500 max
OpenBLAS blas_thread_init: pthread_create failed for thread 13 of 24: Resource temporarily unavailable
OpenBLAS blas_thread_init: RLIMIT_NPROC 1400 current, 1500 max
OpenBLAS blas_thread_init: pthread_create failed for thread 14 of 24: Resource temporarily unavailable
OpenBLAS blas_thread_init: RLIMIT_NPROC 1400 current, 1500 max
OpenBLAS blas_thread_init: pthread_create failed for thread 15 of 24: Resource temporarily unavailable
OpenBLAS blas_thread_init: RLIMIT_NPROC 1400 current, 1500 max
OpenBLAS blas_thread_init: pthread_create failed for thread 16 of 24: Resource temporarily unavailable
OpenBLAS blas_thread_init: RLIMIT_NPROC 1400 current, 1500 max
OpenBLAS blas_thread_init: pthread_create failed for thread 17 of 24: Resource temporarily unavailable
OpenBLAS blas_thread_init: RLIMIT_NPROC 1400 current, 1500 max
OpenBLAS blas_thread_init: pthread_create failed for thread 18 of 24: Resource temporarily unavailable
OpenBLAS blas_thread_init: RLIMIT_NPROC 1400 current, 1500 max
OpenBLAS blas_thread_init: pthread_create failed for thread 19 of 24: Resource temporarily unavailable
OpenBLAS blas_thread_init: RLIMIT_NPROC 1400 current, 1500 max
OpenBLAS blas_thread_init: pthread_create failed for thread 20 of 24: Resource temporarily unavailable
OpenBLAS blas_thread_init: RLIMIT_NPROC 1400 current, 1500 max
OpenBLAS blas_thread_init: pthread_create failed for thread 21 of 24: Resource temporarily unavailable
OpenBLAS blas_thread_init: RLIMIT_NPROC 1400 current, 1500 max
OpenBLAS blas_thread_init: pthread_create failed for thread 22 of 24: Resource temporarily unavailable
OpenBLAS blas_thread_init: RLIMIT_NPROC 1400 current, 1500 max
OpenBLAS blas_thread_init: pthread_create failed for thread 23 of 24: Resource temporarily unavailable
OpenBLAS blas_thread_init: RLIMIT_NPROC 1400 current, 1500 max
[ERROR] [UID:1454][2780431] wsgiAppHandler pApp->start_response() return NULL.
Traceback (most recent call last):
  File "/home/engavqti/virtualenv/abontemapp/3.8/lib/python3.8/site-packages/django/core/handlers/wsgi.py", line 132, in __call__
    response = self.get_response(request)
  File "/home/engavqti/virtualenv/abontemapp/3.8/lib/python3.8/site-packages/django/core/handlers/base.py", line 140, in get_response
    response = self._middleware_chain(request)
  File "/home/engavqti/virtualenv/abontemapp/3.8/lib/python3.8/site-packages/django/core/handlers/exception.py", line 55, in inner
    response = get_response(request)
  File "/home/engavqti/virtualenv/abontemapp/3.8/lib/python3.8/site-packages/django/utils/deprecation.py", line 134, in __call__
    response = response or self.get_response(request)
  File "/home/engavqti/virtualenv/abontemapp/3.8/lib/python3.8/site-packages/django/core/handlers/exception.py", line 55, in inner
    response = get_response(request)
  File "/home/engavqti/virtualenv/abontemapp/3.8/lib/python3.8/site-packages/whitenoise/middleware.py", line 60, in __call__
    response = self.get_response(request)
  File "/home/engavqti/virtualenv/abontemapp/3.8/lib/python3.8/site-packages/django/core/handlers/exception.py", line 55, in inner
    response = get_response(request)
  File "/home/engavqti/virtualenv/abontemapp/3.8/lib/python3.8/site-packages/django/utils/deprecation.py", line 134, in __call__
    response = response or self.get_response(request)
  File "/home/engavqti/virtualenv/abontemapp/3.8/lib/python3.8/site-packages/django/core/handlers/exception.py", line 55, in inner
    response = get_response(request)
  File "/home/engavqti/virtualenv/abontemapp/3.8/lib/python3.8/site-packages/django/utils/deprecation.py", line 134, in __call__
    response = response or self.get_response(request)
  File "/home/engavqti/virtualenv/abontemapp/3.8/lib/python3.8/site-packages/django/core/handlers/exception.py", line 55, in inner
    response = get_response(request)
  File "/home/engavqti/virtualenv/abontemapp/3.8/lib/python3.8/site-packages/django/utils/deprecation.py", line 133, in __call__
    response = self.process_request(request)
  File "/home/engavqti/virtualenv/abontemapp/3.8/lib/python3.8/site-packages/django/middleware/common.py", line 53, in process_request
    if self.should_redirect_with_slash(request):
  File "/home/engavqti/virtualenv/abontemapp/3.8/lib/python3.8/site-packages/django/middleware/common.py", line 70, in should_redirect_with_slash
    if not is_valid_path(request.path_info, urlconf):
  File "/home/engavqti/virtualenv/abontemapp/3.8/lib/python3.8/site-packages/django/urls/base.py", line 155, in is_valid_path
    return resolve(path, urlconf)
  File "/home/engavqti/virtualenv/abontemapp/3.8/lib/python3.8/site-packages/django/urls/base.py", line 24, in resolve
    return get_resolver(urlconf).resolve(path)
  File "/home/engavqti/virtualenv/abontemapp/3.8/lib/python3.8/site-packages/django/urls/resolvers.py", line 649, in resolve
    for pattern in self.url_patterns:
  File "/home/engavqti/virtualenv/abontemapp/3.8/lib/python3.8/site-packages/django/utils/functional.py", line 49, in __get__
    res = instance.__dict__[self.name] = self.func(instance)
  File "/home/engavqti/virtualenv/abontemapp/3.8/lib/python3.8/site-packages/django/urls/resolvers.py", line 696, in url_patterns
    patterns = getattr(self.urlconf_module, "urlpatterns", self.urlconf_module)
  File "/home/engavqti/virtualenv/abontemapp/3.8/lib/python3.8/site-packages/django/utils/functional.py", line 49, in __get__
    res = instance.__dict__[self.name] = self.func(instance)
  File "/home/engavqti/virtualenv/abontemapp/3.8/lib/python3.8/site-packages/django/urls/resolvers.py", line 689, in urlconf_module
    return import_module(self.urlconf_name)
  File "/opt/alt/python38/lib64/python3.8/importlib/__init__.py", line 127, in import_module
    return _bootstrap._gcd_import(name[level:], package, level)
  File "<frozen importlib._bootstrap>", line 1014, in _gcd_import
  File "<frozen importlib._bootstrap>", line 991, in _find_and_load
  File "<frozen importlib._bootstrap>", line 975, in _find_and_load_unlocked
  File "<frozen importlib._bootstrap>", line 671, in _load_unlocked
  File "<frozen importlib._bootstrap_external>", line 843, in exec_module
  File "<frozen importlib._bootstrap>", line 219, in _call_with_frames_removed
  File "/home/engavqti/abontemapp/abontem/urls.py", line 17, in <module>
    from farm import views
  File "/home/engavqti/abontemapp/farm/views.py", line 23, in <module>
    import pandas as pd
  File "/home/engavqti/virtualenv/abontemapp/3.8/lib64/python3.8/site-packages/pandas/__init__.py", line 11, in <module>
    __import__(dependency)
  File "/home/engavqti/virtualenv/abontemapp/3.8/lib64/python3.8/site-packages/numpy/__init__.py", line 150, in <module>
    from . import core
  File "/home/engavqti/virtualenv/abontemapp/3.8/lib64/python3.8/site-packages/numpy/core/__init__.py", line 22, in <module>
    from . import multiarray
  File "/home/engavqti/virtualenv/abontemapp/3.8/lib64/python3.8/site-packages/numpy/core/multiarray.py", line 12, in <module>
    from . import overrides
  File "/home/engavqti/virtualenv/abontemapp/3.8/lib64/python3.8/site-packages/numpy/core/overrides.py", line 7, in <module>
    from numpy.core._multiarray_umath import (
KeyboardInterrupt
OSError: LSAPI: Socket read/write error
OSError: LSAPI: Socket read/write error
OSError: LSAPI: Socket read/write error
OSError: LSAPI: Socket read/write error
OSError: LSAPI: Socket read/write error
OSError: LSAPI: Socket read/write error
OSError: LSAPI: Socket read/write error
OSError: LSAPI: Socket read/write error
OSError: LSAPI: Socket read/write error
OSError: LSAPI: Socket read/write error
OSError: LSAPI: Socket read/write error
OSError: LSAPI: Socket read/write error
OSError: LSAPI: Socket read/write error
OSError: LSAPI: Socket read/write error
OSError: LSAPI: Socket read/write error
OSError: LSAPI: Socket read/write error
OSError: LSAPI: Socket read/write error
OSError: LSAPI: Socket read/write error
OSError: LSAPI: Socket read/write error
[UID:1454][3904400] Reached max children process limit: 6, extra: 2, current: 8, busy: 5, please increase LSAPI_CHILDREN.
[UID:1454][3904400] Reached max children process limit: 6, extra: 2, current: 8, busy: 8, please increase LSAPI_CHILDREN.
[UID:1454][3904400] Reached max children process limit: 6, extra: 2, current: 8, busy: 8, please increase LSAPI_CHILDREN.
[UID:1454][3904400] Reached max children process limit: 6, extra: 2, current: 8, busy: 8, please increase LSAPI_CHILDREN.
[UID:1454][3904400] Reached max children process limit: 6, extra: 2, current: 8, busy: 8, please increase LSAPI_CHILDREN.
[UID:1454][3904400] Reached max children process limit: 6, extra: 2, current: 8, busy: 8, please increase LSAPI_CHILDREN.
[UID:1454][3904400] Reached max children process limit: 6, extra: 2, current: 8, busy: 8, please increase LSAPI_CHILDREN.
[UID:1454][3904400] Reached max children process limit: 6, extra: 2, current: 8, busy: 8, please increase LSAPI_CHILDREN.
[UID:1454][3904400] Reached max children process limit: 6, extra: 2, current: 8, busy: 8, please increase LSAPI_CHILDREN.
[UID:1454][3904400] Reached max children process limit: 6, extra: 2, current: 8, busy: 8, please increase LSAPI_CHILDREN.
[UID:1454][3904400] Reached max children process limit: 6, extra: 2, current: 8, busy: 8, please increase LSAPI_CHILDREN.
[UID:1454][3904400] Reached max children process limit: 6, extra: 2, current: 8, busy: 8, please increase LSAPI_CHILDREN.
[UID:1454][3904400] Reached max children process limit: 6, extra: 2, current: 8, busy: 8, please increase LSAPI_CHILDREN.
[UID:1454][3904400] Reached max children process limit: 6, extra: 2, current: 8, busy: 8, please increase LSAPI_CHILDREN.
[UID:1454][3904400] Reached max children process limit: 6, extra: 2, current: 8, busy: 8, please increase LSAPI_CHILDREN.
[UID:1454][3904400] Reached max children process limit: 6, extra: 2, current: 8, busy: 8, please increase LSAPI_CHILDREN.
OSError: LSAPI: Socket read/write error
OSError: LSAPI: Socket read/write error
OSError: LSAPI: Socket read/write error
OSError: LSAPI: Socket read/write error
OSError: LSAPI: Socket read/write error
OSError: LSAPI: Socket read/write error
OSError: LSAPI: Socket read/write error
OSError: LSAPI: Socket read/write error
OSError: LSAPI: Socket read/write error
OSError: LSAPI: Socket read/write error
OSError: LSAPI: Socket read/write error
OSError: LSAPI: Socket read/write error
OSError: LSAPI: Socket read/write error
OSError: LSAPI: Socket read/write error
OSError: LSAPI: Socket read/write error
OSError: LSAPI: Socket read/write error
OSError: LSAPI: Socket read/write error
OSError: LSAPI: Socket read/write error
OSError: LSAPI: Socket read/write error
OSError: LSAPI: Socket read/write error
OSError: LSAPI: Socket read/write error
OSError: LSAPI: Socket read/write error
OSError: LSAPI: Socket read/write error
OSError: LSAPI: Socket read/write error
OSError: LSAPI: Socket read/write error
OSError: LSAPI: Socket read/write error
OSError: LSAPI: Socket read/write error
OSError: LSAPI: Socket read/write error
OSError: LSAPI: Socket read/write error
OSError: LSAPI: Socket read/write error
OSError: LSAPI: Socket read/write error
OSError: LSAPI: Socket read/write error
OSError: LSAPI: Socket read/write error
OSError: LSAPI: Socket read/write error
OpenBLAS blas_thread_init: pthread_create failed for thread 9 of 24: Resource temporarily unavailable
OpenBLAS blas_thread_init: RLIMIT_NPROC 1400 current, 1500 max
OpenBLAS blas_thread_init: pthread_create failed for thread 10 of 24: Resource temporarily unavailable
OpenBLAS blas_thread_init: RLIMIT_NPROC 1400 current, 1500 max
OpenBLAS blas_thread_init: pthread_create failed for thread 11 of 24: Resource temporarily unavailable
OpenBLAS blas_thread_init: RLIMIT_NPROC 1400 current, 1500 max
OpenBLAS blas_thread_init: pthread_create failed for thread 12 of 24: Resource temporarily unavailable
OpenBLAS blas_thread_init: RLIMIT_NPROC 1400 current, 1500 max
OpenBLAS blas_thread_init: pthread_create failed for thread 13 of 24: Resource temporarily unavailable
OpenBLAS blas_thread_init: RLIMIT_NPROC 1400 current, 1500 max
OpenBLAS blas_thread_init: pthread_create failed for thread 14 of 24: Resource temporarily unavailable
OpenBLAS blas_thread_init: RLIMIT_NPROC 1400 current, 1500 max
OpenBLAS blas_thread_init: pthread_create failed for thread 15 of 24: Resource temporarily unavailable
OpenBLAS blas_thread_init: RLIMIT_NPROC 1400 current, 1500 max
OpenBLAS blas_thread_init: pthread_create failed for thread 16 of 24: Resource temporarily unavailable
OpenBLAS blas_thread_init: RLIMIT_NPROC 1400 current, 1500 max
OpenBLAS blas_thread_init: pthread_create failed for thread 17 of 24: Resource temporarily unavailable
OpenBLAS blas_thread_init: RLIMIT_NPROC 1400 current, 1500 max
OpenBLAS blas_thread_init: pthread_create failed for thread 18 of 24: Resource temporarily unavailable
OpenBLAS blas_thread_init: RLIMIT_NPROC 1400 current, 1500 max
OpenBLAS blas_thread_init: pthread_create failed for thread 19 of 24: Resource temporarily unavailable
OpenBLAS blas_thread_init: RLIMIT_NPROC 1400 current, 1500 max
OpenBLAS blas_thread_init: pthread_create failed for thread 20 of 24: Resource temporarily unavailable
OpenBLAS blas_thread_init: RLIMIT_NPROC 1400 current, 1500 max
OpenBLAS blas_thread_init: pthread_create failed for thread 21 of 24: Resource temporarily unavailable
OpenBLAS blas_thread_init: RLIMIT_NPROC 1400 current, 1500 max
OpenBLAS blas_thread_init: pthread_create failed for thread 22 of 24: Resource temporarily unavailable
OpenBLAS blas_thread_init: RLIMIT_NPROC 1400 current, 1500 max
OpenBLAS blas_thread_init: pthread_create failed for thread 23 of 24: Resource temporarily unavailable
OpenBLAS blas_thread_init: RLIMIT_NPROC 1400 current, 1500 max
[ERROR] [UID:1454][488894] wsgiAppHandler pApp->start_response() return NULL.
Traceback (most recent call last):
  File "/home/engavqti/virtualenv/abontemapp/3.8/lib/python3.8/site-packages/django/core/handlers/exception.py", line 55, in inner
    response = get_response(request)
  File "/home/engavqti/virtualenv/abontemapp/3.8/lib/python3.8/site-packages/django/utils/deprecation.py", line 133, in __call__
    response = self.process_request(request)
  File "/home/engavqti/virtualenv/abontemapp/3.8/lib/python3.8/site-packages/django/middleware/common.py", line 48, in process_request
    host = request.get_host()
  File "/home/engavqti/virtualenv/abontemapp/3.8/lib/python3.8/site-packages/django/http/request.py", line 149, in get_host
    raise DisallowedHost(msg)
django.core.exceptions.DisallowedHost: Invalid HTTP_HOST header: 'mail.abontem.com'. You may need to add 'mail.abontem.com' to ALLOWED_HOSTS.

During handling of the above exception, another exception occurred:

Traceback (most recent call last):
  File "/home/engavqti/virtualenv/abontemapp/3.8/lib/python3.8/site-packages/django/core/handlers/wsgi.py", line 132, in __call__
    response = self.get_response(request)
  File "/home/engavqti/virtualenv/abontemapp/3.8/lib/python3.8/site-packages/django/core/handlers/base.py", line 140, in get_response
    response = self._middleware_chain(request)
  File "/home/engavqti/virtualenv/abontemapp/3.8/lib/python3.8/site-packages/django/core/handlers/exception.py", line 55, in inner
    response = get_response(request)
  File "/home/engavqti/virtualenv/abontemapp/3.8/lib/python3.8/site-packages/django/utils/deprecation.py", line 134, in __call__
    response = response or self.get_response(request)
  File "/home/engavqti/virtualenv/abontemapp/3.8/lib/python3.8/site-packages/django/core/handlers/exception.py", line 55, in inner
    response = get_response(request)
  File "/home/engavqti/virtualenv/abontemapp/3.8/lib/python3.8/site-packages/whitenoise/middleware.py", line 60, in __call__
    response = self.get_response(request)
  File "/home/engavqti/virtualenv/abontemapp/3.8/lib/python3.8/site-packages/django/core/handlers/exception.py", line 55, in inner
    response = get_response(request)
  File "/home/engavqti/virtualenv/abontemapp/3.8/lib/python3.8/site-packages/django/utils/deprecation.py", line 134, in __call__
    response = response or self.get_response(request)
  File "/home/engavqti/virtualenv/abontemapp/3.8/lib/python3.8/site-packages/django/core/handlers/exception.py", line 55, in inner
    response = get_response(request)
  File "/home/engavqti/virtualenv/abontemapp/3.8/lib/python3.8/site-packages/django/utils/deprecation.py", line 134, in __call__
    response = response or self.get_response(request)
  File "/home/engavqti/virtualenv/abontemapp/3.8/lib/python3.8/site-packages/django/core/handlers/exception.py", line 57, in inner
    response = response_for_exception(request, exc)
  File "/home/engavqti/virtualenv/abontemapp/3.8/lib/python3.8/site-packages/django/core/handlers/exception.py", line 133, in response_for_exception
    response = get_exception_response(
  File "/home/engavqti/virtualenv/abontemapp/3.8/lib/python3.8/site-packages/django/core/handlers/exception.py", line 162, in get_exception_response
    callback = resolver.resolve_error_handler(status_code)
  File "/home/engavqti/virtualenv/abontemapp/3.8/lib/python3.8/site-packages/django/urls/resolvers.py", line 710, in resolve_error_handler
    callback = getattr(self.urlconf_module, "handler%s" % view_type, None)
  File "/home/engavqti/virtualenv/abontemapp/3.8/lib/python3.8/site-packages/django/utils/functional.py", line 49, in __get__
    res = instance.__dict__[self.name] = self.func(instance)
  File "/home/engavqti/virtualenv/abontemapp/3.8/lib/python3.8/site-packages/django/urls/resolvers.py", line 689, in urlconf_module
    return import_module(self.urlconf_name)
  File "/opt/alt/python38/lib64/python3.8/importlib/__init__.py", line 127, in import_module
    return _bootstrap._gcd_import(name[level:], package, level)
  File "<frozen importlib._bootstrap>", line 1014, in _gcd_import
  File "<frozen importlib._bootstrap>", line 991, in _find_and_load
  File "<frozen importlib._bootstrap>", line 975, in _find_and_load_unlocked
  File "<frozen importlib._bootstrap>", line 671, in _load_unlocked
  File "<frozen importlib._bootstrap_external>", line 843, in exec_module
  File "<frozen importlib._bootstrap>", line 219, in _call_with_frames_removed
  File "/home/engavqti/abontemapp/abontem/urls.py", line 17, in <module>
    from farm import views
  File "/home/engavqti/abontemapp/farm/views.py", line 23, in <module>
    import pandas as pd
  File "/home/engavqti/virtualenv/abontemapp/3.8/lib64/python3.8/site-packages/pandas/__init__.py", line 11, in <module>
    __import__(dependency)
  File "/home/engavqti/virtualenv/abontemapp/3.8/lib64/python3.8/site-packages/numpy/__init__.py", line 150, in <module>
    from . import core
  File "/home/engavqti/virtualenv/abontemapp/3.8/lib64/python3.8/site-packages/numpy/core/__init__.py", line 22, in <module>
    from . import multiarray
  File "/home/engavqti/virtualenv/abontemapp/3.8/lib64/python3.8/site-packages/numpy/core/multiarray.py", line 12, in <module>
    from . import overrides
  File "/home/engavqti/virtualenv/abontemapp/3.8/lib64/python3.8/site-packages/numpy/core/overrides.py", line 7, in <module>
    from numpy.core._multiarray_umath import (
KeyboardInterrupt
OSError: LSAPI: Socket read/write error
OSError: LSAPI: Socket read/write error
OSError: LSAPI: Socket read/write error
OSError: LSAPI: Socket read/write error
OSError: LSAPI: Socket read/write error
OSError: LSAPI: Socket read/write error
OSError: LSAPI: Socket read/write error
OSError: LSAPI: Socket read/write error
OSError: LSAPI: Socket read/write error
OSError: LSAPI: Socket read/write error
OSError: LSAPI: Socket read/write error
OSError: LSAPI: Socket read/write error
OSError: LSAPI: Socket read/write error
OSError: LSAPI: Socket read/write error
OSError: LSAPI: Socket read/write error
OSError: LSAPI: Socket read/write error
OSError: LSAPI: Socket read/write error
OSError: LSAPI: Socket read/write error
OSError: LSAPI: Socket read/write error
OSError: LSAPI: Socket read/write error
OSError: LSAPI: Socket read/write error
OSError: LSAPI: Socket read/write error
OSError: LSAPI: Socket read/write error
OSError: LSAPI: Socket read/write error
OSError: LSAPI: Socket read/write error
OSError: LSAPI: Socket read/write error
io.UnsupportedOperation: fileno
io.UnsupportedOperation: fileno
io.UnsupportedOperation: fileno
io.UnsupportedOperation: fileno
io.UnsupportedOperation: fileno
io.UnsupportedOperation: fileno
io.UnsupportedOperation: fileno
io.UnsupportedOperation: fileno
io.UnsupportedOperation: fileno
io.UnsupportedOperation: fileno
io.UnsupportedOperation: fileno
io.UnsupportedOperation: fileno
OSError: LSAPI: Socket read/write error
OSError: LSAPI: Socket read/write error
OSError: LSAPI: Socket read/write error
OSError: LSAPI: Socket read/write error
OSError: LSAPI: Socket read/write error
OSError: LSAPI: Socket read/write error
OSError: LSAPI: Socket read/write error
OSError: LSAPI: Socket read/write error
OSError: LSAPI: Socket read/write error
OSError: LSAPI: Socket read/write error
OSError: LSAPI: Socket read/write error
OSError: LSAPI: Socket read/write error
OSError: LSAPI: Socket read/write error
OSError: LSAPI: Socket read/write error
OSError: LSAPI: Socket read/write error
OSError: LSAPI: Socket read/write error
OSError: LSAPI: Socket read/write error
OSError: LSAPI: Socket read/write error
OSError: LSAPI: Socket read/write error
OSError: LSAPI: Socket read/write error
OSError: LSAPI: Socket read/write error
OSError: LSAPI: Socket read/write error
OSError: LSAPI: Socket read/write error
